Exception on /predict [POST]
Traceback (most recent call last):
  File "C:\Users\jeet\AppData\Local\Programs\Python\Python311\Lib\site-packages\flask\app.py", line 2525, in wsgi_app
    response = self.full_dispatch_request()
               ^^^^^^^^^^^^^^^^^^^^^^^^^^^^
  File "C:\Users\jeet\AppData\Local\Programs\Python\Python311\Lib\site-packages\flask\app.py", line 1822, in full_dispatch_request
    rv = self.handle_user_exception(e)
         ^^^^^^^^^^^^^^^^^^^^^^^^^^^^^
  File "C:\Users\jeet\AppData\Local\Programs\Python\Python311\Lib\site-packages\flask\app.py", line 1820, in full_dispatch_request
    rv = self.dispatch_request()
         ^^^^^^^^^^^^^^^^^^^^^^^
  File "C:\Users\jeet\AppData\Local\Programs\Python\Python311\Lib\site-packages\flask\app.py", line 1796, in dispatch_request
    return self.ensure_sync(self.view_functions[rule.endpoint])(**view_args)
           ^^^^^^^^^^^^^^^^^^^^^^^^^^^^^^^^^^^^^^^^^^^^^^^^^^^^^^^^^^^^^^^^^
  File "C:\Users\jeet\AppData\Local\Programs\Python\Python311\Lib\site-packages\flask_login\utils.py", line 290, in decorated_view
    return current_app.ensure_sync(func)(*args, **kwargs)
           ^^^^^^^^^^^^^^^^^^^^^^^^^^^^^^^^^^^^^^^^^^^^^^
  File "C:\Users\jeet\Desktop\boston_price_flask_app\app.py", line 92, in predict
    predicted_price = model.Predict([rooms_count, ptratio, lstat])
                      ^^^^^^^^^^^^^^^^^^^^^^^^^^^^^^^^^^^^^^^^^^^^
  File "C:\Users\jeet\Desktop\boston_price_flask_app\model.py", line 35, in Predict
    result = model.predict(to_predict_list)
             ^^^^^^^^^^^^^^^^^^^^^^^^^^^^^^
  File "C:\Users\jeet\AppData\Local\Programs\Python\Python311\Lib\site-packages\sklearn\ensemble\_forest.py", line 981, in predict
    X = self._validate_X_predict(X)
        ^^^^^^^^^^^^^^^^^^^^^^^^^^^
  File "C:\Users\jeet\AppData\Local\Programs\Python\Python311\Lib\site-packages\sklearn\ensemble\_forest.py", line 602, in _validate_X_predict
    X = self._validate_data(X, dtype=DTYPE, accept_sparse="csr", reset=False)
        ^^^^^^^^^^^^^^^^^^^^^^^^^^^^^^^^^^^^^^^^^^^^^^^^^^^^^^^^^^^^^^^^^^^^^
  File "C:\Users\jeet\AppData\Local\Programs\Python\Python311\Lib\site-packages\sklearn\base.py", line 569, in _validate_data
    self._check_n_features(X, reset=reset)
  File "C:\Users\jeet\AppData\Local\Programs\Python\Python311\Lib\site-packages\sklearn\base.py", line 370, in _check_n_features
    raise ValueError(
ValueError: X has 3 features, but RandomForestRegressor is expecting 4 features as input.
